Workbook

Sheet Contenido
B5: DIAGNÓSTICO DEL NIVEL DE IMPLEMENTACIÓN DEL SISTEMA INTEGRADO DE GESTIÓN | C5: Contexto de la Organización | D5: Liderazgo | E5: Planificación | F5: Apoyo | G5: Operación | H5: Evaluación del Desempeño | I5: Mejora | J5: CUMPLE
B6: RESULTADO ESPERADO | C6: 0.98 | D6: 0.98 | E6: 0.98 | F6: 0.98 | G6: 0.98 | H6: 0.98 | I6: 0.98 | J6: 0.98
A7: GC | B7: GESTIÓN DE LA CALIDAD | C7: =+SGC!G41 | D7: =+SGC!G86 | E7: =+SGC!G131 | F7: =+SGC!G226 | G7: =+SGC!G424 -> - | H7: =+SGC!G491 | I7: =+SGC!G522 | J7: =+IFERROR(+AVERAGE(C7,D7,E7,F7,G7,H7,I7),"")
A8: GMA | B8: GESTIÓN MEDIOAMBIENTAL | C8: =+SGA!G37 | D8: =+SGA!G69 | E8: =+SGA!G139 | F8: =+SGA!G203 | G8: =+SGA!G229 | H8: =+SGA!G297 | I8: =+SGA!G322 | J8: =+IFERROR(+AVERAGE(C8,D8,E8,F8,G8,H8,I8),"")
A9: GSST | B9: GESTIÓN DE LA SEGURIDAD Y SALUD EN EL TRABAJO | C9: =+SST!G25 | D9: =+SST!G72 | E9: =+SST!G146 | F9: =+SST!G212 | G9: =+SST!G270 | H9: =+SST!G322 | I9: =+SST!G350 | J9: =+IFERROR(+AVERAGE(C9,D9,E9,F9,G9,H9,I9),"")
B15: DESARROLLADO POR

Sheet SGC
B1: DIAGNÓSTICO PREVIO - SGC. ISO 9001:2015 | D1: ÍNDICE
A3: 4 | B3: CONTEXTO DE LA ORGANIZACIÓN
A4: 4.1 | B4: Comprensión de la organización y su contexto
A5: 1 | B5: La organización ha determinado las cuestiones externas e internas que son pertinentes para su propósito y su dirección estratégica. | D5: =+IF(C5="","",+IF(C5=0,"No Cumple",+IF(C5=1,"Cumple Parcial",+IF(C5=2,"Cumple Completo",+IF(C5="N","NA")))))
A6: =1+A5 -> 2 | B6: La organización hace seguimiento y revisa la información sobre estas cuestiones externas e internas. | D6: =+IF(C6="","",+IF(C6=0,"No Cumple",+IF(C6=1,"Cumple Parcial",+IF(C6=2,"Cumple Completo",+IF(C6="N","NA")))))
C7: =SUM(C5:C6) -> 0 | D7: =+COUNT(C5:C6)*2 -> 0 | E7: =+IF(C5="","",C7/D7)
A9: 4.2 | B9: Comprensión de las necesidades y expectativas de las partes interesadas
A10: =1+A6 -> 3 | B10: la organización determina las partes interesadas que son pertinentes al SGC | D10: =+IF(C10="","",+IF(C10=0,"No Cumple",+IF(C10=1,"Cumple Parcial",+IF(C10=2,"Cumple Completo",+IF(C10="N","NA")))))
A11: =1+A10 -> 4 | B11: La organización determina los requisitos de sus partes interesadas para el SGC | D11: =+IF(C11="","",+IF(C11=0,"No Cumple",+IF(C11=1,"Cumple Parcial",+IF(C11=2,"Cumple Completo",+IF(C11="N","NA")))))
A12: =1+A11 -> 5 | B12: La organización hace seguimiento y revisión de la información de sus partes interesadas y su requisitos pertinentes. | D12: =+IF(C12="","",+IF(C12=0,"No Cumple",+IF(C12=1,"Cumple Parcial",+IF(C12=2,"Cumple Completo",+IF(C12="N","NA")))))
C13: =SUM(C10:C12) -> 0 | D13: =+COUNT(C10:C12)*2 -> 0 | E13: =+IF(C10="","",C13/D13)
A15: 4.3 | B15: Determinación del alcance del sistema de gestión de la calidad
A16: =1+A12 -> 6 | B16: La organización determina los límites y la aplicabilidad del SGC para establecer su alcance. | D16: =+IF(C16="","",+IF(C16=0,"No Cumple",+IF(C16=1,"Cumple Parcial",+IF(C16=2,"Cumple Completo",+IF(C16="N","NA")))))
A17: =1+A16 -> 7 | B17: Al determinar el alcance, la organización considera: | D17: =+IF(C17="","",+IF(C17=0,"No Cumple",+IF(C17=1,"Cumple Parcial",+IF(C17=2,"Cumple Completo",+IF(C17="N","NA")))))
A18: =1+A17 -> 8 | B18: a) Las cuestiones externas e internas que son pertinentes. | D18: =+IF(C18="","",+IF(C18=0,"No Cumple",+IF(C18=1,"Cumple Parcial",+IF(C18=2,"Cumple Completo",+IF(C18="N","NA")))))
A19: =1+A18 -> 9 | B19: b) Los requisitos de las partes interesadas pertinentes. | D19: =+IF(C19="","",+IF(C19=0,"No Cumple",+IF(C19=1,"Cumple Parcial",+IF(C19=2,"Cumple Completo",+IF(C19="N","NA")))))
A20: =1+A19 -> 10 | B20: c) Los productos y servicios de la organización | D20: =+IF(C20="","",+IF(C20=0,"No Cumple",+IF(C20=1,"Cumple Parcial",+IF(C20=2,"Cumple Completo",+IF(C20="N","NA")))))
A21: =1+A20 -> 11 | B21: El alcance proporciona la justificación para cualquier requisito de esta Norma que la organización determine que no es aplicable para el alcance del SGC. | D21: =+IF(C21="","",+IF(C21=0,"No Cumple",+IF(C21=1,"Cumple Parcial",+IF(C21=2,"Cumple Completo",+IF(C21="N","NA")))))
A22: =1+A21 -> 12 | B22: La organización dispone y mantiene información documentada relacionada con el alcance del SGC. | D22: =+IF(C22="","",+IF(C22=0,"No Cumple",+IF(C22=1,"Cumple Parcial",+IF(C22=2,"Cumple Completo",+IF(C22="N","NA")))))
C23: =SUM(C16:C22) -> 0 | D23: =+COUNT(C16:C22)*2 -> 0 | E23: =+IF(C16="","",C23/D23)
A25: 4.4 | B25: Sistema de gestión de la calidad y sus procesos
A26: 4.4.1 | B26: Generalidades sobre gestión de procesos y mejora continua
A27: =1+A22 -> 13 | B27: La organización debe establecer, implementar, mantener y mejorar continuamente un SGC, incluidos los procesos y sus interacciones, de acuerdo a esta norma internacional, y debe: | D27: =+IF(C27="","",+IF(C27=0,"No Cumple",+IF(C27=1,"Cumple Parcial",+IF(C27=2,"Cumple Completo",+IF(C27="N","NA")))))
A28: =1+A27 -> 14 | B28: a) Determinar las entradas requeridas y las salidas esperadas de estos procesos | D28: =+IF(C28="","",+IF(C28=0,"No Cumple",+IF(C28=1,"Cumple Parcial",+IF(C28=2,"Cumple Completo",+IF(C28="N","NA")))))
A29: =1+A28 -> 15 | B29: b) Determinar la secuencia e interacción de los procesos | D29: =+IF(C29="","",+IF(C29=0,"No Cumple",+IF(C29=1,"Cumple Parcial",+IF(C29=2,"Cumple Completo",+IF(C29="N","NA")))))
A30: =1+A29 -> 16 | B30: c) Determinar y aplicar los criterios y los métodos (seguimiento, medición, indicadores del desempeño) | D30: =+IF(C30="","",+IF(C30=0,"No Cumple",+IF(C30=1,"Cumple Parcial",+IF(C30=2,"Cumple Completo",+IF(C30="N","NA")))))
A31: =1+A30 -> 17 | B31: d) Determinar los recursos necesarios para estos procesos y asegurarse de su disponibilidad | D31: =+IF(C31="","",+IF(C31=0,"No Cumple",+IF(C31=1,"Cumple Parcial",+IF(C31=2,"Cumple Completo",+IF(C31="N","NA")))))
A32: =1+A31 -> 18 | B32: e) Asignar las responsabilidades y autoridades para estos procesos | D32: =+IF(C32="","",+IF(C32=0,"No Cumple",+IF(C32=1,"Cumple Parcial",+IF(C32=2,"Cumple Completo",+IF(C32="N","NA")))))
A33: =1+A32 -> 19 | B33: f) Abordar los riesgos y oportunidades determinados de acuerdo con los requisitos del apartado 6.1 | D33: =+IF(C33="","",+IF(C33=0,"No Cumple",+IF(C33=1,"Cumple Parcial",+IF(C33=2,"Cumple Completo",+IF(C33="N","NA")))))
A34: =1+A33 -> 20 | B34: g) Evaluar estos procesos e implementar cualquier cambio necesario para asegurarse de que estos procesos logran los resultados previstos | D34: =+IF(C34="","",+IF(C34=0,"No Cumple",+IF(C34=1,"Cumple Parcial",+IF(C34=2,"Cumple Completo",+IF(C34="N","NA")))))
A35: =1+A34 -> 21 | B35: h) Mejorar los procesos y el sistema de gestión de la calidad | D35: =+IF(C35="","",+IF(C35=0,"No Cumple",+IF(C35=1,"Cumple Parcial",+IF(C35=2,"Cumple Completo",+IF(C35="N","NA")))))
C36: =SUM(C27:C35) -> 0 | D36: =+COUNT(C27:C35)*2 -> 0 | E36: =+IF(C27="","",C36/D36)
A38: 4.4.2 | B38: Documentación de los procesos del SGC
A39: =1+A35 -> 22 | B39: a) Mantener información documentada para apoya la operación de los procesos | D39: =+IF(C39="","",+IF(C39=0,"No Cumple",+IF(C39=1,"Cumple Parcial",+IF(C39=2,"Cumple Completo",+IF(C39="N","NA")))))
A40: =1+A39 -> 23 | B40: b) Conservar la información documentada para tener la confianza de que los procesos se realizan según lo planificado | D40: =+IF(C40="","",+IF(C40=0,"No Cumple",+IF(C40=1,"Cumple Parcial",+IF(C40=2,"Cumple Completo",+IF(C40="N","NA")))))
C41: =SUM(C39:C40) -> 0 | D41: =+COUNT(C39:C40)*2 -> 0 | E41: =+IF(C39="","",C41/D41) | G41: =IFERROR(+AVERAGE(E7,E13,E23,E36,E41),"")
A43: 5 | B43: LIDERAZGO
A44: 5.1 | B44: Liderazgo y compromiso
A45: 5.1.1 | B45: Generalidades
A46: =1+A40 -> 24 | B46: La alta dirección debe demostrar liderazgo y compromiso con respecto al SGC: | D46: =+IF(C46="","",+IF(C46=0,"No Cumple",+IF(C46=1,"Cumple Parcial",+IF(C46=2,"Cumple Completo",+IF(C46="N","NA")))))
...

Sheet SGA
B1: DIAGNÓSTICO PREVIO - SGA. ISO 14001:2015 | D1: ÍNDICE
A3: 4 | B3: CONTEXTO DE LA ORGANIZACIÓN
A4: 4.1 | B4: Comprensión de la organización y su contexto
A5: 1 | B5: La organización ha determinado las cuestiones externas e internas que son pertinentes para su propósito y que afectan su capacidad para lograr los resultados previstos del SGA. | D5: =+IF(C5="","",+IF(C5=0,"No Cumple",+IF(C5=1,"Cumple Parcial",+IF(C5=2,"Cumple Completo",+IF(C5="N","NA")))))
A6: =1+A5 -> 2 | B6: La organización hace seguimiento y revisa la información sobre estas cuestiones externas e internas. | D6: =+IF(C6="","",+IF(C6=0,"No Cumple",+IF(C6=1,"Cumple Parcial",+IF(C6=2,"Cumple Completo",+IF(C6="N","NA")))))
C7: =SUM(C5:C6) -> 0 | D7: =+COUNT(C5:C6)*2 -> 0 | E7: =+IF(C5="","",C7/D7)
A9: 4.2 | B9: Comprensión de las necesidades y expectativas de las partes interesadas
A10: =1+A6 -> 3 | B10: la organización determina las partes interesadas que son pertinentes al SGA | D10: =+IF(C10="","",+IF(C10=0,"No Cumple",+IF(C10=1,"Cumple Parcial",+IF(C10=2,"Cumple Completo",+IF(C10="N","NA")))))
A11: =1+A10 -> 4 | B11: La organización determina las necesidades y expectativas (es decir, requisitos) de estas partes interesadas | D11: =+IF(C11="","",+IF(C11=0,"No Cumple",+IF(C11=1,"Cumple Parcial",+IF(C11=2,"Cumple Completo",+IF(C11="N","NA")))))
A12: =1+A11 -> 5 | B12: La organización determina cuáles de estas necesidades y expectativas se convierten en requisitos legales y otros requisitos | D12: =+IF(C12="","",+IF(C12=0,"No Cumple",+IF(C12=1,"Cumple Parcial",+IF(C12=2,"Cumple Completo",+IF(C12="N","NA")))))
C13: =SUM(C10:C12) -> 0 | D13: =+COUNT(C10:C12)*2 -> 0 | E13: =+IF(C10="","",C13/D13)
A15: 4.3 | B15: Determinación del alcance del sistema de gestión ambiental
A16: =1+A12 -> 6 | B16: La organización determina los límites y la aplicabilidad del SGA para establecer su alcance. | D16: =+IF(C16="","",+IF(C16=0,"No Cumple",+IF(C16=1,"Cumple Parcial",+IF(C16=2,"Cumple Completo",+IF(C16="N","NA")))))
A17: =1+A16 -> 7 | B17: Al determinar el alcance, la organización considera: | D17: =+IF(C17="","",+IF(C17=0,"No Cumple",+IF(C17=1,"Cumple Parcial",+IF(C17=2,"Cumple Completo",+IF(C17="N","NA")))))
A18: =1+A17 -> 8 | B18: a) Las cuestiones externas e internas a que se hace referencia en el apartado 4.1 | D18: =+IF(C18="","",+IF(C18=0,"No Cumple",+IF(C18=1,"Cumple Parcial",+IF(C18=2,"Cumple Completo",+IF(C18="N","NA")))))
A19: =1+A18 -> 9 | B19: b) Los requisitos de las partes interesadas pertinentes, referido en el apartado 4.2 | D19: =+IF(C19="","",+IF(C19=0,"No Cumple",+IF(C19=1,"Cumple Parcial",+IF(C19=2,"Cumple Completo",+IF(C19="N","NA")))))
A20: =1+A19 -> 10 | B20: c) Las unidades, funciones y límites físicos de la organización | D20: =+IF(C20="","",+IF(C20=0,"No Cumple",+IF(C20=1,"Cumple Parcial",+IF(C20=2,"Cumple Completo",+IF(C20="N","NA")))))
A21: =1+A20 -> 11 | B21: d) sus actividades, productos y servicios | D21: =+IF(C21="","",+IF(C21=0,"No Cumple",+IF(C21=1,"Cumple Parcial",+IF(C21=2,"Cumple Completo",+IF(C21="N","NA")))))
A22: =1+A21 -> 12 | B22: e) su autoridad y capacidad para ejercer control e influencia | D22: =+IF(C22="","",+IF(C22=0,"No Cumple",+IF(C22=1,"Cumple Parcial",+IF(C22=2,"Cumple Completo",+IF(C22="N","NA")))))
A23: =1+A22 -> 13 | B23: Una vez que se defina el alcance, se deben incluir en el SGA todas las actividades, productos y servicios de la organización que estén dentro de este alcance. | D23: =+IF(C23="","",+IF(C23=0,"No Cumple",+IF(C23=1,"Cumple Parcial",+IF(C23=2,"Cumple Completo",+IF(C23="N","NA")))))
A24: =1+A23 -> 14 | B24: La organización dispone y mantiene información documentada y debe estar disponible para las partes interesadas. | D24: =+IF(C24="","",+IF(C24=0,"No Cumple",+IF(C24=1,"Cumple Parcial",+IF(C24=2,"Cumple Completo",+IF(C24="N","NA")))))
C25: =SUM(C16:C24) -> 0 | D25: =+COUNT(C16:C24)*2 -> 0 | E25: =+IF(C16="","",C25/D25)
A27: 4.4 | B27: Sistema de gestión de la calidad y sus procesos
A28: =1+A24 -> 15 | B28: La organización debe establecer, implementar, mantener y mejorar continuamente un SGA, incluidos los procesos y sus interacciones, de acuerdo a esta norma internacional, y debe: | D28: =+IF(C28="","",+IF(C28=0,"No Cumple",+IF(C28=1,"Cumple Parcial",+IF(C28=2,"Cumple Completo",+IF(C28="N","NA")))))
A29: =1+A28 -> 16 | B29: a) Determinar las entradas requeridas y las salidas esperadas de estos procesos | D29: =+IF(C29="","",+IF(C29=0,"No Cumple",+IF(C29=1,"Cumple Parcial",+IF(C29=2,"Cumple Completo",+IF(C29="N","NA")))))
A30: =1+A29 -> 17 | B30: b) Determinar la secuencia e interacción de los procesos | D30: =+IF(C30="","",+IF(C30=0,"No Cumple",+IF(C30=1,"Cumple Parcial",+IF(C30=2,"Cumple Completo",+IF(C30="N","NA")))))
A31: =1+A30 -> 18 | B31: c) Determinar y aplicar los criterios y los métodos (seguimiento, medición, indicadores del desempeño) | D31: =+IF(C31="","",+IF(C31=0,"No Cumple",+IF(C31=1,"Cumple Parcial",+IF(C31=2,"Cumple Completo",+IF(C31="N","NA")))))
A32: =1+A31 -> 19 | B32: d) Determinar los recursos necesarios para estos procesos y asegurarse de su disponibilidad | D32: =+IF(C32="","",+IF(C32=0,"No Cumple",+IF(C32=1,"Cumple Parcial",+IF(C32=2,"Cumple Completo",+IF(C32="N","NA")))))
A33: =1+A32 -> 20 | B33: e) Asignar las responsabilidades y autoridades para estos procesos | D33: =+IF(C33="","",+IF(C33=0,"No Cumple",+IF(C33=1,"Cumple Parcial",+IF(C33=2,"Cumple Completo",+IF(C33="N","NA")))))
A34: =1+A33 -> 21 | B34: f) Abordar los riesgos y oportunidades determinados de acuerdo con los requisitos del apartado 6.1 | D34: =+IF(C34="","",+IF(C34=0,"No Cumple",+IF(C34=1,"Cumple Parcial",+IF(C34=2,"Cumple Completo",+IF(C34="N","NA")))))
A35: =1+A34 -> 22 | B35: Al establecer y mantener el SGA, la organización debe considerar el conocimiento obtenido en los apartados 4.1 y 4.2 | D35: =+IF(C35="","",+IF(C35=0,"No Cumple",+IF(C35=1,"Cumple Parcial",+IF(C35=2,"Cumple Completo",+IF(C35="N","NA")))))
A36: =1+A35 -> 23 | B36: h) Mejorar los procesos y el sistema de gestión ambiental | D36: =+IF(C36="","",+IF(C36=0,"No Cumple",+IF(C36=1,"Cumple Parcial",+IF(C36=2,"Cumple Completo",+IF(C36="N","NA")))))
C37: =SUM(C28:C36) -> 0 | D37: =+COUNT(C28:C36)*2 -> 0 | E37: =+IF(C28="","",C37/D37) | G37: =+IF(E7="","",+AVERAGE(E7,E13,E25,E37))
A39: 5.1 | B39: Liderazgo y compromiso
A40: 5.1.1 | B40: Generalidades
A41: =1+A36 -> 24 | B41: La alta dirección debe demostrar liderazgo y compromiso con respecto al SGA: | D41: =+IF(C41="","",+IF(C41=0,"No Cumple",+IF(C41=1,"Cumple Parcial",+IF(C41=2,"Cumple Completo",+IF(C41="N","NA")))))
A42: =1+A41 -> 25 | B42: a) asumiendo la responsabilidad y obligación de rendir cuentas con relación a la eficacia del SGA | D42: =+IF(C42="","",+IF(C42=0,"No Cumple",+IF(C42=1,"Cumple Parcial",+IF(C42=2,"Cumple Completo",+IF(C42="N","NA")))))
A43: =1+A42 -> 26 | B43: b) asegurándose de que se establezcan la política y los objetivos ambientales para el SGA, y que estos sean compatibles con el contexto y la dirección estratégica de la organización | D43: =+IF(C43="","",+IF(C43=0,"No Cumple",+IF(C43=1,"Cumple Parcial",+IF(C43=2,"Cumple Completo",+IF(C43="N","NA")))))
A44: =1+A43 -> 27 | B44: c) asegurándose de la integración de los requisitos del SGA en los procesos de negocio de la organización | D44: =+IF(C44="","",+IF(C44=0,"No Cumple",+IF(C44=1,"Cumple Parcial",+IF(C44=2,"Cumple Completo",+IF(C44="N","NA")))))
A45: =1+A44 -> 28 | B45: d) asegurándose de que los recursos necesarios para el SGA estén disponibles | D45: =+IF(C45="","",+IF(C45=0,"No Cumple",+IF(C45=1,"Cumple Parcial",+IF(C45=2,"Cumple Completo",+IF(C45="N","NA")))))
...

Sheet SST
B1: ANÁLISIS DE BRECHAS (GAP ANALYSIS) SG-SST | D1: ÍNDICE
A2: 4. | B2: CONTEXTO DE LA ORGANIZACIÓN
A3: 4.1 | B3: Comprensión de la organización y su contexto
A4: 1 | B4: La organización debe determinar las cuestiones externas e internas que son pertinentes para su propósito y que afecta a su capacidad para alcanzar los resultados previstos de su sistema de gestión de la SST. | D4: =+IF(C4="","",+IF(C4=0,"No Cumple",+IF(C4=1,"Cumple Parcial",+IF(C4=2,"Cumple Completo",+IF(C4="N","NA")))))
A5: =1+A4 -> 2 | B5: Ejemplos de factores del contexto externo que pueden obtenerse a través del análisis de PESTAL incluye: 1. Grupos de presión y sindicatos de trabajadores; 2. Aseguradores y stakeholder Vistas; 3. Las condiciones económicas; 4. Las expectativas sociales y prioridades politicas; 5. La legislación y la observancia; 6. Las agencias nacionales/internacionales. Ejemplos de de contexto interno que pueden obtenerse a través del análisis DOFA (SWOT) incluye: 1. Estructura, responsabilidades, competencias y control; 2. Nuevos productos, asuntos contractuales, cooperación y comunicaciones. | D5: =+IF(C5="","",+IF(C5=0,"No Cumple",+IF(C5=1,"Cumple Parcial",+IF(C5=2,"Cumple Completo",+IF(C5="N","NA")))))
C6: =SUM(C3:C5) -> 0 | D6: =+COUNT(C3:C5)*2 -> 0 | E6: =+IF(C4="","",C6/D6)
A7: 4.2 | B7: Comprensión de las necesidades y expectativas de los trabajadores y otras partes interesadas. La organización debe determinar:
A8: =1+A5 -> 3 | B8: a) Las partes interesadas, además de los trabajadores, que son pertinentes al SG-SST | D8: =+IF(C8="","",+IF(C8=0,"No Cumple",+IF(C8=1,"Cumple Parcial",+IF(C8=2,"Cumple Completo",+IF(C8="N","NA")))))
A9: =1+A8 -> 4 | B9: b) las necesidades y expectativas pertinentes (es decir, los requisitos) de los trabajadores y de otras partes interesadas | D9: =+IF(C9="","",+IF(C9=0,"No Cumple",+IF(C9=1,"Cumple Parcial",+IF(C9=2,"Cumple Completo",+IF(C9="N","NA")))))
A10: =1+A9 -> 5 | B10: c) cuáles de las necesidades y expectativas son o podrían convertirse, en requisitos legales y otros requisitos. | D10: =+IF(C10="","",+IF(C10=0,"No Cumple",+IF(C10=1,"Cumple Parcial",+IF(C10=2,"Cumple Completo",+IF(C10="N","NA")))))
A11: =1+A10 -> 6 | B11: ¿Quién podría afectar o verse afectado por sus actividades y cuáles podrían ser sus intereses relevantes y significativos? ¿Ha tenido en cuenta sus necesidades dentro sistema de gestión de la SST ? 1. Necesidades y expectaciones tanto de gestión y trabajadores no directivos y representantes de los trabajadores (donde existan); 2. Afectan al SG-SST o que se perciben afectados por el SG-SST (a. 4.2); 3. Trabajador y representantes apropiados de los trabajadores; 4. Requisitos legal y regulatorios 5. Otras organizaciones relacionados o perteneciente a un grupo 6. Proveedores, contratistas y subcontratistas; 7. Las organizaciones de trabajadores (sindicatos) y las organizaciones de empleadores 8. Propietarios, accionistas, clientes, visitantes, comunidad local, vecinos, público en general; 9. Salud ocupacional y organizaciones de seguridad; profesionales de seguridad y salud ocupacional (p. ej., médicos, enfermeras). | D11: =+IF(C11="","",+IF(C11=0,"No Cumple",+IF(C11=1,"Cumple Parcial",+IF(C11=2,"Cumple Completo",+IF(C11="N","NA")))))
C12: =SUM(C8:C11) -> 0 | D12: =+COUNT(C8:C11)*2 -> 0 | E12: =+IF(C8="","",C12/D12)
A13: 4.3 | B13: Determinación del alcance del SG-SST
A14: =1+A11 -> 7 | B14: La organización debe determinar los límites y la aplicabilidad del SG-SST para establecer su alcance. | D14: =+IF(C14="","",+IF(C14=0,"No Cumple",+IF(C14=1,"Cumple Parcial",+IF(C14=2,"Cumple Completo",+IF(C14="N","NA")))))
A15: =1+A14 -> 8 | B15: Cuando se determine su alcance, la organización debe: a) Considerar las cuestiones externas e internas indicadas en el apartado 4.1 | D15: =+IF(C15="","",+IF(C15=0,"No Cumple",+IF(C15=1,"Cumple Parcial",+IF(C15=2,"Cumple Completo",+IF(C15="N","NA")))))
A16: =1+A15 -> 9 | B16: b) Tener en cuenta los requisitos indicados en el apartado 4.2 | D16: =+IF(C16="","",+IF(C16=0,"No Cumple",+IF(C16=1,"Cumple Parcial",+IF(C16=2,"Cumple Completo",+IF(C16="N","NA")))))
A17: =1+A16 -> 10 | B17: c) tener en cuenta las actividades relacionadas con el trabajo, planificadas o relacionadas | D17: =+IF(C17="","",+IF(C17=0,"No Cumple",+IF(C17=1,"Cumple Parcial",+IF(C17=2,"Cumple Completo",+IF(C17="N","NA")))))
A18: =1+A17 -> 11 | B18: El SG-SST debe incluir las actividades, los productos y los servicios bajo el control o la influencia de la organización que pueden tener impacto en el desempeño de la SST de la organización. | D18: =+IF(C18="","",+IF(C18=0,"No Cumple",+IF(C18=1,"Cumple Parcial",+IF(C18=2,"Cumple Completo",+IF(C18="N","NA")))))
A19: =1+A18 -> 12 | B19: El alcance debe estar disponible como información documentada. | D19: =+IF(C19="","",+IF(C19=0,"No Cumple",+IF(C19=1,"Cumple Parcial",+IF(C19=2,"Cumple Completo",+IF(C19="N","NA")))))
A20: =1+A19 -> 13 | B20: Asegúrese de que la aplicación del alcance sea relevante para: 1. Las cuestiones externas e internas mencionadas en el 4,1; 2. Requisitos contemplados en el 4,2; 3. el tipos de actividades relacionadas con el trabajo realizadas. Cualquier cambio en el alcance debe estar sujeto a los requisitos de la norma y sujeta a auditoría mediante la evaluación de la conformidad. | D20: =+IF(C20="","",+IF(C20=0,"No Cumple",+IF(C20=1,"Cumple Parcial",+IF(C20=2,"Cumple Completo",+IF(C20="N","NA")))))
C21: =SUM(C14:C16) -> 0 | D21: =+COUNT(C14:C16)*2 -> 0 | E21: =+IF(C14="","",C21/D21)
A22: 4.4 | B22: Sistema de gestión de la SST
A23: =1+A20 -> 14 | B23: La organización debe establecer, implementar, mantener y mejorar continuamente un SG-SST, incluidos los procesos necesarios y sus interacciones, de acuerdo con los requisitos de este documento. | D23: =+IF(C23="","",+IF(C23=0,"No Cumple",+IF(C23=1,"Cumple Parcial",+IF(C23=2,"Cumple Completo",+IF(C23="N","NA")))))
A24: =1+A23 -> 15 | B24: Se proporciona evidencia útil para demostrar los procesos que sustan las actividades del SG-SST. Contar con una matriz de procesos facilita la planificación, porque proporciona interacción con los requisitos de otras cláusulas, incluidas las relacionadas con el riesgo, la planificación, los recursos y el monitoreo y la medición de los resultados de los sistema de gestión. La matriz de proceso puede ser un elemento útil para presentar en la auditoría. | D24: =+IF(C24="","",+IF(C24=0,"No Cumple",+IF(C24=1,"Cumple Parcial",+IF(C24=2,"Cumple Completo",+IF(C24="N","NA")))))
C25: =SUM(C23:C24) -> 0 | D25: =+COUNT(C23:C24)*2 -> 0 | E25: =+IF(C23="","",C25/D25) | G25: =+IF(E6="","",+AVERAGE(E6,E12,E25))
A26: 5 | B26: LIDERAZGO Y PARTICIPACIÓN DE LOS TRABAJADORES
A27: 5.1 | B27: Liderazgo y compromiso La lata dirección debe demostrar liderazgo y compromiso con respecto al SG-SST:
A28: =1+A24 -> 16 | B28: a) Asumiendo la total responsabilidad y rendición de cuentas para la prevención de las lesiones y el deterioro de la salud relacionados con el trabajo, así como la provisión de actividades y lugares de trabajo seguros y saludables | D28: =+IF(C28="","",+IF(C28=0,"No Cumple",+IF(C28=1,"Cumple Parcial",+IF(C28=2,"Cumple Completo",+IF(C28="N","NA")))))
A29: =1+A28 -> 17 | B29: b) asegurándose de que se establezcan la política de la SST y los objetivos relacionados con la SST y sean compatibles con la dirección estratégica de la organización. | D29: =+IF(C29="","",+IF(C29=0,"No Cumple",+IF(C29=1,"Cumple Parcial",+IF(C29=2,"Cumple Completo",+IF(C29="N","NA")))))
A30: =1+A29 -> 18 | B30: c) asegurándose de la integración de los requisitos del SG-SST en los procesos de negocio de la organización. | D30: =+IF(C30="","",+IF(C30=0,"No Cumple",+IF(C30=1,"Cumple Parcial",+IF(C30=2,"Cumple Completo",+IF(C30="N","NA")))))
A31: =1+A30 -> 19 | B31: d) asegurándose de que los recursos necesarios para establecer, implementar, mantener y mejorar el SG-SST estén disponibles. | D31: =+IF(C31="","",+IF(C31=0,"No Cumple",+IF(C31=1,"Cumple Parcial",+IF(C31=2,"Cumple Completo",+IF(C31="N","NA")))))
A32: =1+A31 -> 20 | B32: e) comunicando la importancia de una gestión de SST eficaz y conforme con los requisitos del SG-SST. | D32: =+IF(C32="","",+IF(C32=0,"No Cumple",+IF(C32=1,"Cumple Parcial",+IF(C32=2,"Cumple Completo",+IF(C32="N","NA")))))
A33: =1+A32 -> 21 | B33: f) asegurándose de que el SG-SST alcance los resultados previstos. | D33: =+IF(C33="","",+IF(C33=0,"No Cumple",+IF(C33=1,"Cumple Parcial",+IF(C33=2,"Cumple Completo",+IF(C33="N","NA")))))
A34: =1+A33 -> 22 | B34: g) dirigiendo y apoyando a las personas, para contribuir a la eficacia del SG-SST. | D34: =+IF(C34="","",+IF(C34=0,"No Cumple",+IF(C34=1,"Cumple Parcial",+IF(C34=2,"Cumple Completo",+IF(C34="N","NA")))))
A35: =1+A34 -> 23 | B35: h) asegurando y promoviendo la mejora continua. | D35: =+IF(C35="","",+IF(C35=0,"No Cumple",+IF(C35=1,"Cumple Parcial",+IF(C35=2,"Cumple Completo",+IF(C35="N","NA")))))
A36: =1+A35 -> 24 | B36: i) apoyando otros roles pertinentes de la dirección, para demostrar su liderazgo aplicado a sus áreas de responsabilidad. | D36: =+IF(C36="","",+IF(C36=0,"No Cumple",+IF(C36=1,"Cumple Parcial",+IF(C36=2,"Cumple Completo",+IF(C36="N","NA")))))
A37: =1+A36 -> 25 | B37: j) desarrollando, liderando y promoviendo una cultura en la organización que apoye los resultados previstos del SG-SST. | D37: =+IF(C37="","",+IF(C37=0,"No Cumple",+IF(C37=1,"Cumple Parcial",+IF(C37=2,"Cumple Completo",+IF(C37="N","NA")))))
A38: =1+A37 -> 26 | B38: k) protegiendo a los trabajadores de represalias al informar de incidentes, peligros, riesgos y oportunidades. | D38: =+IF(C38="","",+IF(C38=0,"No Cumple",+IF(C38=1,"Cumple Parcial",+IF(C38=2,"Cumple Completo",+IF(C38="N","NA")))))
A39: =1+A38 -> 27 | B39: l) asegurándose de que la organización establezca e implemente procesos para la consulta y la participación de los trabajadores. | D39: =+IF(C39="","",+IF(C39=0,"No Cumple",+IF(C39=1,"Cumple Parcial",+IF(C39=2,"Cumple Completo",+IF(C39="N","NA")))))
A40: =1+A39 -> 28 | B40: m) apoyando el establecimiento y funcionamiento de comités de seguridad y salud (véase 5.4-e) | D40: =+IF(C40="","",+IF(C40=0,"No Cumple",+IF(C40=1,"Cumple Parcial",+IF(C40=2,"Cumple Completo",+IF(C40="N","NA")))))
...
